Workbook

Sheet Overview
B2: Frostvale: all game text in English · සිංහල · தமிழ்
B3: Exported from the game source on 23 October 2026. The Sinhala and Tamil text was written by AI: please have native speakers review it.
B5: Area | C5: Lines | D5: Sinhala OK | E5: Tamil OK | F5: Needs change
B6: Game UI | C6: =COUNTIF(Translations!$B$2:$B$306,B6) -> 155 | D6: =COUNTIFS(Translations!$B$2:$B$306,B6,Translations!$J$2:$J$306,"OK") -> 0 | E6: =COUNTIFS(Translations!$B$2:$B$306,B6,Translations!$K$2:$K$306,"OK") -> 0 | F6: =COUNTIFS(Translations!$B$2:$B$306,B6,Translations!$J$2:$J$306,"Needs change")+COUNTIFS(Translations!$B$2:$B$306,B6,Translations!$K$2:$K$306,"Needs change") -> 0
B7: Advent Dice Race | C7: =COUNTIF(Translations!$B$2:$B$306,B7) -> 28 | D7: =COUNTIFS(Translations!$B$2:$B$306,B7,Translations!$J$2:$J$306,"OK") -> 0 | E7: =COUNTIFS(Translations!$B$2:$B$306,B7,Translations!$K$2:$K$306,"OK") -> 0 | F7: =COUNTIFS(Translations!$B$2:$B$306,B7,Translations!$J$2:$J$306,"Needs change")+COUNTIFS(Translations!$B$2:$B$306,B7,Translations!$K$2:$K$306,"Needs change") -> 0
B8: Cookie Catch | C8: =COUNTIF(Translations!$B$2:$B$306,B8) -> 9 | D8: =COUNTIFS(Translations!$B$2:$B$306,B8,Translations!$J$2:$J$306,"OK") -> 0 | E8: =COUNTIFS(Translations!$B$2:$B$306,B8,Translations!$K$2:$K$306,"OK") -> 0 | F8: =COUNTIFS(Translations!$B$2:$B$306,B8,Translations!$J$2:$J$306,"Needs change")+COUNTIFS(Translations!$B$2:$B$306,B8,Translations!$K$2:$K$306,"Needs change") -> 0
B9: Elf Workshop | C9: =COUNTIF(Translations!$B$2:$B$306,B9) -> 31 | D9: =COUNTIFS(Translations!$B$2:$B$306,B9,Translations!$J$2:$J$306,"OK") -> 0 | E9: =COUNTIFS(Translations!$B$2:$B$306,B9,Translations!$K$2:$K$306,"OK") -> 0 | F9: =COUNTIFS(Translations!$B$2:$B$306,B9,Translations!$J$2:$J$306,"Needs change")+COUNTIFS(Translations!$B$2:$B$306,B9,Translations!$K$2:$K$306,"Needs change") -> 0
B10: Krampus' Cellar | C10: =COUNTIF(Translations!$B$2:$B$306,B10) -> 12 | D10: =COUNTIFS(Translations!$B$2:$B$306,B10,Translations!$J$2:$J$306,"OK") -> 0 | E10: =COUNTIFS(Translations!$B$2:$B$306,B10,Translations!$K$2:$K$306,"OK") -> 0 | F10: =COUNTIFS(Translations!$B$2:$B$306,B10,Translations!$J$2:$J$306,"Needs change")+COUNTIFS(Translations!$B$2:$B$306,B10,Translations!$K$2:$K$306,"Needs change") -> 0
B11: Mini-game names & how-to | C11: =COUNTIF(Translations!$B$2:$B$306,B11) -> 40 | D11: =COUNTIFS(Translations!$B$2:$B$306,B11,Translations!$J$2:$J$306,"OK") -> 0 | E11: =COUNTIFS(Translations!$B$2:$B$306,B11,Translations!$K$2:$K$306,"OK") -> 0 | F11: =COUNTIFS(Translations!$B$2:$B$306,B11,Translations!$J$2:$J$306,"Needs change")+COUNTIFS(Translations!$B$2:$B$306,B11,Translations!$K$2:$K$306,"Needs change") -> 0
B12: Santa's Express | C12: =COUNTIF(Translations!$B$2:$B$306,B12) -> 19 | D12: =COUNTIFS(Translations!$B$2:$B$306,B12,Translations!$J$2:$J$306,"OK") -> 0 | E12: =COUNTIFS(Translations!$B$2:$B$306,B12,Translations!$K$2:$K$306,"OK") -> 0 | F12: =COUNTIFS(Translations!$B$2:$B$306,B12,Translations!$J$2:$J$306,"Needs change")+COUNTIFS(Translations!$B$2:$B$306,B12,Translations!$K$2:$K$306,"Needs change") -> 0
B13: Snowball Showdown | C13: =COUNTIF(Translations!$B$2:$B$306,B13) -> 10 | D13: =COUNTIFS(Translations!$B$2:$B$306,B13,Translations!$J$2:$J$306,"OK") -> 0 | E13: =COUNTIFS(Translations!$B$2:$B$306,B13,Translations!$K$2:$K$306,"OK") -> 0 | F13: =COUNTIFS(Translations!$B$2:$B$306,B13,Translations!$J$2:$J$306,"Needs change")+COUNTIFS(Translations!$B$2:$B$306,B13,Translations!$K$2:$K$306,"Needs change") -> 0
B14: Server | C14: =COUNTIF(Translations!$B$2:$B$306,B14) -> 1 | D14: =COUNTIFS(Translations!$B$2:$B$306,B14,Translations!$J$2:$J$306,"OK") -> 0 | E14: =COUNTIFS(Translations!$B$2:$B$306,B14,Translations!$K$2:$K$306,"OK") -> 0 | F14: =COUNTIFS(Translations!$B$2:$B$306,B14,Translations!$J$2:$J$306,"Needs change")+COUNTIFS(Translations!$B$2:$B$306,B14,Translations!$K$2:$K$306,"Needs change") -> 0
B15: Total | C15: =SUM(C6:C14) -> 305 | D15: =SUM(D6:D14) -> 0 | E15: =SUM(E6:E14) -> 0 | F15: =SUM(F6:F14) -> 0
B17: Review progress
B18: Sinhala reviewed (OK) | C18: =IF(C15=0,0,D15/C15) -> 0
B19: Tamil reviewed (OK) | C19: =IF(C15=0,0,E15/C15) -> 0
B21: How to review
B22: • Translations sheet: one line of game text per row, English beside Sinhala and Tamil.
B23: • Set "Sinhala review" / "Tamil review" to OK or Needs change (drop-down). This table updates by itself.
B24: • Write fixes only in the yellow columns: Corrected Sinhala, Corrected Tamil and Reviewer notes.
B25: • Keep {placeholders} such as {n} or {game} exactly as they are: the game fills them in.
B26: • Keep HTML tags like <b>…</b> and <kbd>E</kbd>, emoji, ★ and key names (WASD, Space, Esc) as they are.
B27: • Form "singular" / "plural": the game picks one by the number {n}.
B28: • Example: Key "jump" reads පනින්න. If a better word fits, set Sinhala review to Needs change and type it under Corrected Sinhala.
B29: • Glossary sheet: the shared words every screen uses. Agree these first, then the rest follows.
B30: • Sinhala and Tamil columns use the Nirmala UI font (Windows). On a Mac the system picks a Sinhala/Tamil font itself.
B32: Yellow cells = for reviewers to fill in

Sheet Translations
A1: # | B1: Area | C1: Section | D1: Key | E1: Form | F1: English | G1: සිංහල Sinhala | H1: தமிழ் Tamil | I1: Placeholders | J1: Sinhala review | K1: Tamil review | L1: Corrected Sinhala | M1: Corrected Tamil | N1: Reviewer notes | O1: Source file
A2: 1 | B2: Game UI | C2: HUD | D2: hintDesktop | F2: WASD move · Mouse look · Shift sprint · Space jump · F snowball · E play · M map · C passport · L leaders · Esc settings | G2: WASD ගමන් කරන්න · මූසිකයෙන් බලන්න · Shift දුවන්න · Space පනින්න · F හිම බෝලය · E ක්‍රීඩා කරන්න · M සිතියම · C ගමන් බලපත්‍රය · L ප්‍රමුඛයෝ · Esc සැකසුම් | H2: WASD நகர · மவுஸ் பார் · Shift ஓடு · Space குதி · F பனிப்பந்து · E விளையாடு · M வரைபடம் · C கடவுச்சீட்டு · L முன்னிலை · Esc அமைப்புகள் | J2: To review | K2: To review | O2: src/i18n/ui.ts
A3: 2 | B3: Game UI | C3: HUD | D3: hintTouch | F3: Left thumb: move (push far to run) · Right thumb: look · ⤒ jump · ❄️ throw a snowball (in the snow) | G3: වම් මාපටැඟිල්ල: ගමන් කරන්න (දුවන්න දුරට තල්ලු කරන්න) · දකුණු මාපටැඟිල්ල: බලන්න · ⤒ පනින්න · ❄️ හිම බෝලයක් විසි කරන්න (හිම මත) | H3: இடது கட்டைவிரல்: நகர (ஓட தூரமாகத் தள்ளுங்கள்) · வலது கட்டைவிரல்: பார் · ⤒ குதி · ❄️ பனிப்பந்து எறி (பனியில்) | J3: To review | K3: To review | O3: src/i18n/ui.ts
A4: 3 | B4: Game UI | C4: HUD | D4: loadingWrap | F4: Wrapping presents… | G4: තෑගි ඔතමින්… | H4: பரிசுகளைப் பொதி செய்கிறோம்… | J4: To review | K4: To review | O4: src/i18n/ui.ts
A5: 4 | B5: Game UI | C5: HUD | D5: loadingPct | F5: Loading… {pct} | G5: පූරණය වෙමින්… {pct} | H5: ஏற்றுகிறது… {pct} | I5: {pct} | J5: To review | K5: To review | O5: src/i18n/ui.ts
A6: 5 | B6: Game UI | C6: HUD | D6: almostReady | F6: Almost ready… | G6: තව ටිකයි… | H6: கிட்டத்தட்ட தயார்… | J6: To review | K6: To review | O6: src/i18n/ui.ts
A7: 6 | B7: Game UI | C7: HUD | D7: titleLead | F7: The six golden ornaments of the Great Tree have been scattered across the village. Find each festive challenge, win its ornament, and light the tree before Christmas Eve. | G7: මහා ගසේ රන් සැරසිලි හයම ගම පුරා විසිරිලා. හැම උත්සව අභියෝගයක්ම සොයාගෙන, එහි සැරසිල්ල දිනලා, නත්තල් ඊවට කලින් ගස දල්වන්න. | H7: பெரிய மரத்தின் ஆறு தங்க அலங்காரப் பந்துகள் கிராமம் முழுவதும் சிதறிவிட்டன. ஒவ்வொரு பண்டிகைச் சவாலையும் கண்டுபிடித்து, அதன் அலங்காரப் பந்தை வென்று, கிறிஸ்துமஸ் ஈவுக்கு முன் மரத்தை ஒளிரச் செய்யுங்கள். | J7: To review | K7: To review | O7: src/i18n/ui.ts
A8: 7 | B8: Game UI | C8: HUD | D8: titleStats | F8: {games} challenges · {orn} ornaments found · ⭐ {stars}/18 | G8: අභියෝග {games} · සැරසිලි {orn}ක් හමුවුණා · ⭐ {stars}/18 | H8: {games} சவால்கள் · {orn} அலங்காரப் பந்துகள் கிடைத்தன · ⭐ {stars}/18 | I8: {games}, {orn}, {stars} | J8: To review | K8: To review | O8: src/i18n/ui.ts
A9: 8 | B9: Game UI | C9: HUD | D9: titleTouch | F9: Left thumb moves · right thumb looks · tap <b>▶ Play</b> at a glowing beacon | G9: වම් මාපටැඟිල්ලෙන් ගමන් කරන්න · දකුණු මාපටැඟිල්ලෙන් බලන්න · දිලිසෙන ආලෝකයක් ළඟ <b>▶ ක්‍රීඩා කරන්න</b> තට්ටු කරන්න | H9: இடது கட்டைவிரல் நகர்த்தும் · வலது கட்டைவிரல் பார்க்கும் · ஒளிரும் விளக்கின் அருகே <b>▶ விளையாடு</b> தொடுங்கள் | J9: To review | K9: To review | O9: src/i18n/ui.ts
A10: 9 | B10: Game UI | C10: HUD | D10: continue | F10: Continue | G10: දිගටම යමු | H10: தொடரவும் | J10: To review | K10: To review | O10: src/i18n/ui.ts
A11: 10 | B11: Game UI | C11: HUD | D11: startExploring | F11: Start exploring | G11: ගවේෂණය අරඹන්න | H11: ஆராயத் தொடங்கு | J11: To review | K11: To review | O11: src/i18n/ui.ts
A12: 11 | B12: Game UI | C12: HUD | D12: playChip | F12: ▶ Play | G12: ▶ ක්‍රීඩා කරන්න | H12: ▶ விளையாடு | J12: To review | K12: To review | O12: src/i18n/ui.ts
A13: 12 | B13: Game UI | C13: HUD | D13: pressE | F13: Press <kbd>E</kbd> to play {game} | G13: {game} ක්‍රීඩා කිරීමට <kbd>E</kbd> ඔබන්න | H13: {game} விளையாட <kbd>E</kbd> அழுத்துங்கள் | I13: {game} | J13: To review | K13: To review | O13: src/i18n/ui.ts
A14: 13 | B14: Game UI | C14: HUD | D14: guest | F14: Guest | G14: අමුත්තා | H14: விருந்தினர் | J14: To review | K14: To review | O14: src/i18n/ui.ts
A15: 14 | B15: Game UI | C15: HUD | D15: guestBadge | F15: Guest · open your passport | G15: අමුත්තා · ඔබේ ගමන් බලපත්‍රය විවෘත කරන්න | H15: விருந்தினர் · உங்கள் கடவுச்சீட்டைத் திறக்கவும் | J15: To review | K15: To review | O15: src/i18n/ui.ts
A16: 15 | B16: Game UI | C16: HUD | D16: mapTitle | F16: Map of Frostvale | G16: ෆ්‍රොස්ට්වේල් සිතියම | H16: ஃப்ராஸ்ட்வேல் வரைபடம் | J16: To review | K16: To review | O16: src/i18n/ui.ts
A17: 16 | B17: Game UI | C17: HUD | D17: greatTree | F17: Great Tree | G17: මහා ගස | H17: பெரிய மரம் | J17: To review | K17: To review | O17: src/i18n/ui.ts
A18: 17 | B18: Game UI | C18: HUD | D18: mapCloseTouch | F18: Tap anywhere to close | G18: වසා දැමීමට ඕනෑම තැනක තට්ටු කරන්න | H18: மூட எங்காவது தொடுங்கள் | J18: To review | K18: To review | O18: src/i18n/ui.ts
A19: 18 | B19: Game UI | C19: HUD | D19: mapCloseDesk | F19: M or click to close | G19: වසා දැමීමට M හෝ ක්ලික් කරන්න | H19: மூட M அல்லது கிளிக் செய்யுங்கள் | J19: To review | K19: To review | O19: src/i18n/ui.ts
A20: 19 | B20: Game UI | C20: HUD | D20: bestStars | F20: best: {stars} | G20: හොඳම: {stars} | H20: சிறந்தது: {stars} | I20: {stars} | J20: To review | K20: To review | O20: src/i18n/ui.ts
A21: 20 | B21: Game UI | C21: HUD | D21: noStars | F21: no stars yet | G21: තවම තරු නැහැ | H21: இன்னும் நட்சத்திரம் இல்லை | J21: To review | K21: To review | O21: src/i18n/ui.ts
A22: 21 | B22: Game UI | C22: HUD | D22: notNow | F22: Not now | G22: දැන් නොවේ | H22: இப்போது இல்லை | J22: To review | K22: To review | O22: src/i18n/ui.ts
A23: 22 | B23: Game UI | C23: HUD | D23: playBang | F23: Play! | G23: ක්‍රීඩා කරමු! | H23: விளையாடு! | J23: To review | K23: To review | O23: src/i18n/ui.ts
A24: 23 | B24: Game UI | C24: HUD | D24: elvesBuilding | F24: 🧝 The elves are still building this one — check back soon! | G24: 🧝 එල්ෆ්ලා තවම මේක හදනවා — ඉක්මනින් ආයෙත් බලන්න! | H24: 🧝 எல்ஃப்கள் இதை இன்னும் உருவாக்குகிறார்கள் — விரைவில் மீண்டும் பாருங்கள்! | J24: To review | K24: To review | O24: src/i18n/ui.ts
A25: 24 | B25: Game UI | C25: HUD | D25: ok | F25: OK | G25: හරි | H25: சரி | J25: To review | K25: To review | O25: src/i18n/ui.ts
A26: 25 | B26: Game UI | C26: HUD | D26: score | F26: Score: <b>{score}</b> | G26: ලකුණු: <b>{score}</b> | H26: புள்ளிகள்: <b>{score}</b> | I26: {score} | J26: To review | K26: To review | O26: src/i18n/ui.ts
A27: 26 | B27: Game UI | C27: HUD | D27: earnedOrnament | F27: 🟡 You earned a golden ornament! | G27: 🟡 ඔබ රන් සැරසිල්ලක් දිනුවා! | H27: 🟡 நீங்கள் ஒரு தங்க அலங்காரப் பந்தை வென்றீர்கள்! | J27: To review | K27: To review | O27: src/i18n/ui.ts
A28: 27 | B28: Game UI | C28: HUD | D28: needStar | F28: Get at least one star to earn the ornament. | G28: සැරසිල්ල දිනන්න අඩුම තරම තරුවක්වත් ගන්න. | H28: அலங்காரப் பந்தை வெல்ல குறைந்தது ஒரு நட்சத்திரம் பெறுங்கள். | J28: To review | K28: To review | O28: src/i18n/ui.ts
A29: 28 | B29: Game UI | C29: HUD | D29: backToFrostvale | F29: Back to Frostvale | G29: ෆ්‍රොස්ට්වේල් වෙත ආපසු | H29: ஃப்ராஸ்ட்வேலுக்குத் திரும்பு | J29: To review | K29: To review | O29: src/i18n/ui.ts
A30: 29 | B30: Game UI | C30: HUD | D30: leaveGameAria | F30: Leave game | G30: ක්‍රීඩාවෙන් ඉවත් වන්න | H30: விளையாட்டை விட்டு வெளியேறு | J30: To review | K30: To review | O30: src/i18n/ui.ts
A31: 30 | B31: Game UI | C31: HUD | D31: passportAria | F31: Your passport | G31: ඔබේ ගමන් බලපත්‍රය | H31: உங்கள் கடவுச்சீட்டு | J31: To review | K31: To review | O31: src/i18n/ui.ts
A32: 31 | B32: Game UI | C32: HUD | D32: growingForest | F32: Growing the forest… | G32: වනාන්තරය වවමින්… | H32: காட்டை வளர்க்கிறோம்… | J32: To review | K32: To review | O32: src/i18n/ui.ts
A33: 32 | B33: Game UI | C33: HUD | D33: decorating | F33: Decorating the village… | G33: ගම සරසමින්… | H33: கிராமத்தை அலங்கரிக்கிறோம்… | J33: To review | K33: To review | O33: src/i18n/ui.ts
A34: 33 | B34: Game UI | C34: Touch buttons | D34: jump | F34: JUMP | G34: පනින්න | H34: குதி | J34: To review | K34: To review | O34: src/i18n/ui.ts
A35: 34 | B35: Game UI | C35: Touch buttons | D35: throw | F35: THROW | G35: විසි කරන්න | H35: எறி | J35: To review | K35: To review | O35: src/i18n/ui.ts
A36: 35 | B36: Game UI | C36: Touch buttons | D36: jumpAria | F36: Jump | G36: පනින්න | H36: குதி | J36: To review | K36: To review | O36: src/i18n/ui.ts
A37: 36 | B37: Game UI | C37: Touch buttons | D37: snowballAria | F37: Snowball | G37: හිම බෝලය | H37: பனிப்பந்து | J37: To review | K37: To review | O37: src/i18n/ui.ts
A38: 37 | B38: Game UI | C38: Touch buttons | D38: mapAria | F38: Map | G38: සිතියම | H38: வரைபடம் | J38: To review | K38: To review | O38: src/i18n/ui.ts
... A44: 43 | B44: Game UI | C44: Mini-game frame | D44: leave | F44: Leave | G44: ඉවත් වන්න | H44: வெளியேறு | J44: To review | K44: To review | O44: src/i18n/ui.ts
A45: 44 | B45: Game UI | C45: Toasts | D45: ornamentHung | F45: 🟡 {game} ornament hung on the Great Tree! ({n}/6) | G45: 🟡 {game} සැරසිල්ල මහා ගසේ එල්ලුවා! ({n}/6) | H45: 🟡 {game} அலங்காரப் பந்து பெரிய மரத்தில் தொங்கவிடப்பட்டது! ({n}/6) | I45: {game}, {n} | J45: To review | K45: To review | O45: src/i18n/ui.ts
...

Sheet Glossary
A1: Group | B1: English | C1: සිංහල Sinhala | D1: தமிழ் Tamil | E1: Sinhala review | F1: Tamil review | G1: Reviewer notes
A2: Shared terms | B2: Frostvale (in sentences) | C2: ෆ්‍රොස්ට්වේල් | D2: ஃப்ராஸ்ட்வேல் | E2: To review | F2: To review
A3: Shared terms | B3: ornament (Christmas tree bauble) | C3: සැරසිල්ල | D3: அலங்காரப் பந்து | E3: To review | F3: To review
A4: Shared terms | B4: star (rating) | C4: තරුව | D4: நட்சத்திரம் | E4: To review | F4: To review
A5: Shared terms | B5: snowball | C5: හිම බෝලය | D5: பனிப்பந்து | E5: To review | F5: To review
A6: Shared terms | B6: snowman | C6: හිම මිනිසා | D6: பனிமனிதன் | E6: To review | F6: To review
A7: Shared terms | B7: present / gift | C7: තෑග්ග | D7: பரிசு | E7: To review | F7: To review
A8: Shared terms | B8: elf | C8: එල්ෆ් | D8: எல்ஃப் | E8: To review | F8: To review
A9: Shared terms | B9: Santa | C9: සැන්ටා | D9: சாண்டா | E9: To review | F9: To review
A10: Shared terms | B10: Krampus | C10: ක්‍රැම්පස් | D10: க்ராம்பஸ் | E10: To review | F10: To review
A11: Shared terms | B11: cookie | C11: කුකී | D11: குக்கீ | E11: To review | F11: To review
A12: Shared terms | B12: coal | C12: අඟුරු | D12: கரி | E12: To review | F12: To review
A13: Shared terms | B13: toy | C13: සෙල්ලම් බඩුව | D13: பொம்மை | E13: To review | F13: To review
... A32: Mini-game names | B32: Advent Dice Race | C32: ඇඩ්වෙන්ට් දාදු තරඟය | D32: அட்வென்ட் பகடை பந்தயம் | E32: To review | F32: To review
